Workbook

Sheet Dashboard
R5: =H14-'بنك الضمان '!C69 -> 0
B7: بيان الوحدات المباعة والتحصيل | E7: توزيع حساب الضمات
S8: نسبة الإنجاز الفعلية المثبته في وافي 1-1-2026 | T8: 0.56
B9: البيان | C9: القيمة | E9: البيان | F9: القيمة | G9: المسحوب من حساب الضمان | H9: رصيد حساب الضمان
B10: عدد الوحدات | C10: 40
B11: عدد الوحدات المباعة | C11: =الجدول2[[#Totals],[اسم العميل]] -> 26 | E11: الاعمال الانشائية بنسبة 76% | F11: ='بنك الضمان '!$C$67*0.76 -> 6025755.1 | G11: 4048000 | H11: =F11-G11 -> 1977755.1
B12: نسبة الوحدات المباعة | C12: =C11/C10 -> 0.65 | E12: المصروفات الأخرى 20% | F12: ='بنك الضمان '!$C$67*0.2 -> 1585725 | G12: 1000000 | H12: =F12-G12 -> 585725.02
B13: إجمالي المبيعات لكامل المشروع | C13: =الجدول2[[#Totals],[قيمة الوحدة ]] -> 15054819 | E13: حساب الضمان من بداية المشروع 4% | F13: ='بنك الضمان '!$C$67*0.04 -> 317145 | H13: =F13-G13 -> 317145
B14: اجمالي المبيعات للوحدات المحجوزه | C14: =SUMIFS(الجدول2[[قيمة الوحدة ]],الجدول2[تاريخ الحجز],"<>") -> 19679098 | E14: الإجمالي | F14: =SUM(F11:F13) -> 7928625.1 | G14: =SUM(G11:G13) -> 5048000 | H14: =SUM(H11:H13) -> 2880625.1
B15: الدفعات المحصلة | C15: =الجدول2[[#Totals],[إجمالي الدفعات المحصلة]] -> 8415474.1
B16: نسبة التحصيل من الوحدات المحجوزة | C16: =C15/C14 -> 0.42763515
B17: نسبة التحصيل من كامل المشروع | C17: =C15/C13 -> 0.55898873
B19: تكاليف المشروع | E19: العمولات على المشروع
B21: البيان | C21: القيمة | E21: البيان | F21: القيمة
B22: التكلفة المرصودة للمشروع مع الأرض | C22: 17000000 | E22: العمولة | F22: =الجدول2[[#Totals],[العمولة ]] -> 509100.16
B23: التكلفة الفعلية | C23: 14419002 | E23: المكافات | F23: =الجدول2[[#Totals],[مكافاة البيع ]] -> 68138
B24: المتبقي من تكلفة المشروع | C24: =C22-C23 -> 2580998
B25: نسبة التكلفة الفعلية | C25: =C23/C22 -> 0.84817659 | E25: الإجمالي | F25: =SUM(F22:F24) -> 577238.16

Sheet بنك الضمان 
A8: Account Statement Report
B12: Account Number | C12: SA5480000504608019900183
B13: Account Name | C13: قصر القصور مائة واثنان وثلاثون
B14: Currency | C14: SAR
B15: Statement Date | C15: 12/04/2026
B16: Duration | C16: 01/02/2026 - 13/04/2026
B17: Duration Hijra | C17: 1447/08/13 - 1447/10/25
B18: Opening Balance | C18: 0.00
B19: Closing Balance | C19: 2,210,562.10
B22: Date | C22: HijiraDate | D22: Time | E22: Transaction Description | F22: Remark | G22: Transaction Type | H22: Credit | I22: Debit | J22: Balance | K22: Channel Type
B23: 08/02/2026 | C23: 1447/08/20 | D23: 19:58 | E23: Internal Transfer | F23: W-/FRACCT/13100608010426031FRعبدالوهاب | G23: Credit | H23: 1 | I23: 0 | J23: 1 | K23: Mobile
B24: 09/02/2026 | C24: 1447/08/21 | D24: 09:05 | E24: Inward Local Payment Order | F24: Payment-NCBK82826038AQNB-NCBK99626040000M-بندر عبدالله العقل-KASER ALKOSOR ONE HUNDRED THIRTY TW | G24: Credit | H24: 546000 | I24: 0 | J24: 546001 | K24: Other
B25: 09/02/2026 | C25: 1447/08/21 | D25: 14:26 | E25: Internal Transfer | F25: W-/FRACCT/14400608010607130FRمنى | G25: Credit | H25: 248500 | I25: 0 | J25: 794501 | K25: Mobile
B26: 10/02/2026 | C26: 1447/08/22 | D26: 11:48 | E26: Inward Local Payment Order | F26: Payment-1109FT26041N93C3-INMAINM2604100C1-هيله محمد عبدالله الصعب-KASER ALKOSOR ONE HUNDRED THIRTY T | G26: Credit | H26: 280000 | I26: 0 | J26: 1074501 | K26: Other
B27: 10/02/2026 | C27: 1447/08/22 | D27: 19:03 | E27: Internal Transfer | F27: W-/FRACCT/29600608010060971FRماجد | G27: Credit | H27: 245700 | I27: 0 | J27: 1320201 | K27: Mobile
B28: 14/02/2026 | C28: 1447/08/26 | D28: 17:40 | E28: Internal Transfer | F28: W-/FRACCT/34100608010027520FRاحمد | G28: Credit | H28: 294850 | I28: 0 | J28: 1615051 | K28: Mobile
B29: 15/02/2026 | C29: 1447/08/27 | D29: 08:04 | E29: Internal Transfer | F29: W-/FRACCT/34100608010027520FRاحمد | G29: Credit | H29: 294850 | I29: 0 | J29: 1909901 | K29: Mobile
B30: 16/02/2026 | C30: 1447/08/28 | D30: 14:33 | E30: Inward Local Payment Order | F30: Payment-NCBK2142604706Y2-NCBK9962604702LP-منى علي الغامدي-قصر القصور مائة واثنان وثلاثون | G30: Credit | H30: 471400 | I30: 0 | J30: 2381301 | K30: Other
B31: 19/02/2026 | C31: 1447/09/02 | D31: 10:11 | E31: Inward Local Payment Order | F31: Payment-ML45169502-ARNBFPQ260505922-FATIMAH ALI KHORMI-قصر القصور مائة واثنان وثلاثون | G31: Credit | H31: 287325 | I31: 0 | J31: 2668626 | K31: Other
B32: 19/02/2026 | C32: 1447/09/02 | D32: 14:09 | E32: Transfer To Customer Account | F32: تحويل عبدالسلام علي عثمان البراك / الدفعة الاولى من قصر القصور حي السعادة | G32: Credit | H32: 281843 | I32: 0 | J32: 2950469
B33: 19/02/2026 | C33: 1447/09/02 | D33: 23:58 | E33: Internal Transfer | F33: W-/FRACCT/29600608010657396FRعبدالرحمن | G33: Credit | H33: 104200 | I33: 0 | J33: 3054669 | K33: Mobile
B34: 20/02/2026 | C34: 1447/09/03 | D34: 00:09 | E34: Internal Transfer | F34: W-/FRACCT/29600608010657396FRعبدالرحمن | G34: Credit | H34: 101470 | I34: 0 | J34: 3156139 | K34: Mobile
B35: 23/02/2026 | C35: 1447/09/06 | D35: 14:37 | E35: Inward Local Payment Order | F35: Payment-6054120DC0030107-ARNBFPQ260546635-ABDULRAHMAN DAKHIL AALMELHEM-شركة قصر القصور للاستثمار | G35: Credit | H35: 250000 | I35: 0 | J35: 3406139 | K35: Other
B36: 23/02/2026 | C36: 1447/09/06 | D36: 16:35 | E36: Internal Transfer | F36: W-/FRACCT/44900608010295508FRمحمد | G36: Credit | H36: 248875 | I36: 0 | J36: 3655014 | K36: Mobile
B37: 24/02/2026 | C37: 1447/09/07 | D37: 11:17 | E37: Transfer To Customer Account | F37: تحويل محمد صالح عبدالرحمن القنيطير / دفعه نصف المبلغ لشراء شقة رقم 2 حي السعادة للاخت هدى صالح القني | G37: Credit | H37: 300000 | I37: 0 | J37: 3955014
B38: 24/02/2026 | C38: 1447/09/07 | D38: 22:21 | E38: Internal Transfer | F38: W-/FRACCT/52100608011685740FRحصة | G38: Credit | H38: 300000 | I38: 0 | J38: 4255014 | K38: Mobile
B39: 25/02/2026 | C39: 1447/09/08 | D39: 00:04 | E39: Internal Transfer | F39: W-/FRACCT/52100608011685740FRحصة | G39: Credit | H39: 19400 | I39: 0 | J39: 4274414 | K39: Mobile
B40: 25/02/2026 | C40: 1447/09/08 | D40: 15:11 | E40: Inward Local Payment Order | F40: Payment-1703FT26056S720H-INMAINM2605600NQ-باسل توفيق ابن احمد بوعيد-قصر القصور مائة واثنان وثلاثون | G40: Credit | H40: 140600 | I40: 0 | J40: 4415014 | K40: Other
B41: 26/02/2026 | C41: 1447/09/09 | D41: 10:26 | E41: Inward Local Payment Order | F41: Payment-LP MAJO000R7-SABBREM26057007U-MOAYAD HUSSAIN A AL RASASI-قصر القصور مائة واثنان وثلا ثون | G41: Credit | H41: 309935 | I41: 0 | J41: 4724949 | K41: Other
B42: 26/02/2026 | C42: 1447/09/09 | D42: 15:09 | E42: Transfer To Customer Account | F42: تحويل عبدالرحمن صالح محمد المطلق / دفعة مقدمة من شراء شقة | G42: Credit | H42: 328500 | I42: 0 | J42: 5053449
B43: 26/02/2026 | C43: 1447/09/09 | D43: 15:16 | E43: Inward Local Payment Order | F43: Payment-6057111DC0041919-ARNBFPQ260577980-RAWAH SAEED HULWAH-قصر القصور مائة واثنان وثلاثون | G43: Credit | H43: 273000 | I43: 0 | J43: 5326449 | K43: Other
B44: 01/03/2026 | C44: 1447/09/12 | D44: 00:20 | E44: Inward Local Payment Order | F44: Payment-941700570951GCS0-RIBLPEM2605801OY-ابراهيم سعد عبدالكريم البلم-قصر القصور مائة واثنان وثلاثون | G44: Credit | H44: 150000 | I44: 0 | J44: 5476449 | K44: Other
B45: 01/03/2026 | C45: 1447/09/12 | D45: 00:26 | E45: Inward Local Payment Order | F45: Payment-941700570951GCS2-RIBLPEM2605801OY-سعد ابراهيم سعد البلم-قصر القصور مائة واثنان وثلاثون | G45: Credit | H45: 100000 | I45: 0 | J45: 5576449 | K45: Other
B46: 02/03/2026 | C46: 1447/09/13 | D46: 15:58 | E46: Transfer To Customer Account | F46: تحويل صفاء احمد حمدان الغامدي / الدفعه الاولى 50% للوحده رقم 16 | G46: Credit | H46: 335370 | I46: 0 | J46: 5911819
B47: 05/03/2026 | C47: 1447/09/16 | D47: 15:03 | E47: Inward Local Payment Order | F47: Payment-EPHR98126064PJ1F-BSFRPYC2606401G2-ANDALIB SAEED - HULWAH-قصر القصور مائة واثنان وثلاثون | G47: Credit | H47: 279825 | I47: 0 | J47: 6191644 | K47: Other
B48: 11/03/2026 | C48: 1447/09/22 | D48: 02:42 | E48: Internal Transfer | F48: W-/FRACCT/29600608010657396FRعبدالرحمن | G48: Credit | H48: 156300 | I48: 0 | J48: 6347944 | K48: Mobile
B49: 12/03/2026 | C49: 1447/09/23 | D49: 02:31 | E49: Internal Transfer | F49: W-/FRACCT/29600608010657396FRعبدالرحمن | G49: Credit | H49: 152205 | I49: 0 | J49: 6500149 | K49: Mobile
B50: 01/04/2026 | C50: 1447/10/13 | D50: 04:20 | E50: Inward Local Payment Order | F50: Payment-941700900951J83J-RIBLPEM26091001I-سعد ابراهيم سعد البلم-قصر القصور مائة واثنان وثلاثون | G50: Credit | H50: 61260 | I50: 0 | J50: 6561409 | K50: Other
B51: 02/04/2026 | C51: 1447/10/14 | D51: 12:03 | E51: Sarie Payment Order | F51: EA - REMITTANCE - E260402120245794 - A2A - شركة قصر القصور للاستثمار 83 | G51: Debit Fund Request | H51: 0 | I51: -4048000 | J51: 2513409 | K51: Other
B52: 02/04/2026 | C52: 1447/10/14 | D52: 14:03 | E52: Sarie Payment Order | F52: EA - REMITTANCE - E260402140238392 - A2A - شركة قصر القصور للاستثمار 83 | G52: Debit Fund Request | H52: 0 | I52: -1000000 | J52: 1513409 | K52: Other
...

Sheet العملاء والوحدات
A1: رقم الوحدة | B1: اسم العميل | C1: الدور | D1: المساحة | E1: مواصفات | F1: نوع الحجز | G1: قيمة الوحدة | H1: تاريخ الحجز | I1: تاريخ العقد | J1: إجمالي الدفعات المحصلة | K1: نسبة التحصيل الفعلي | L1: الرصيد المتبقي الفعلي | M1: قيمة الوحدة بدون السعي | N1: العمولة | O1: ضريبة العمولة | P1: العمولة شاملة الضريبة | Q1: مكافاة البيع | R1: العمولة + مكافاة البيع | S1: المسدد من العمولة | T1: المتبقي من العمولة | U1: حالة توقيع العقد | V1: تحصيل 4-2026 إيصال الى 70% | W1: تحصيل 6-2026 إيصال الى 85% | X1: تحصيل 7-2026 إيصال الى 95% | Y1: تحصيل 11-2026 إيصال الى 100% | Z1: اجمالي الوحدة المحصلة | AA1: المتبقي
A2: 1 | B2: سعد بن إبراهيم بن سعد البلم (نسبه التملك 50%) & ابراهيم بن سعد بن عبدالكريم البلم (نسبه التملك 50%) | C2: الأرضي | D2: 149.11 | E2: مجلس | 3 غرف | صالة | مطبخ | 3 حمام | F2: كاش -دفعات | G2: 622520 | H2: 46064 | J2: =SUMIF('الدفعات والتحصيل'!B:B,الجدول2[[#This Row],[رقم الوحدة]],'الدفعات والتحصيل'!D:D) -> 311260 | K2: =IFERROR(الجدول2[[#This Row],[إجمالي الدفعات المحصلة]]/الجدول2[[#This Row],[قيمة الوحدة ]],0) -> 0.5 | L2: ='العملاء والوحدات'!$G2-'العملاء والوحدات'!$J2 -> 311260 | M2: =الجدول2[[#This Row],[قيمة الوحدة ]]/1.035 -> 601468.6 | N2: =الجدول2[[#This Row],[قيمة الوحدة بدون السعي ]]*0.035 -> 21051.401 | O2: =الجدول2[[#This Row],[العمولة ]]*0.15 -> 3157.7101 | P2: =الجدول2[[#This Row],[ضريبة العمولة ]]+الجدول2[[#This Row],[العمولة ]] -> 24209.111 | Q2: 5750 | R2: =الجدول2[[#This Row],[مكافاة البيع ]]+الجدول2[[#This Row],[العمولة شاملة الضريبة ]] -> 29959.111 | S2: =الجدول2[[#This Row],[العمولة + مكافاة البيع]] -> 29959.111 | T2: =الجدول2[[#This Row],[العمولة + مكافاة البيع]]-الجدول2[[#This Row],[المسدد من العمولة ]] -> 0 | V2: =الجدول2[[#This Row],[قيمة الوحدة ]]*0.7-الجدول2[[#This Row],[إجمالي الدفعات المحصلة]] -> 124504 | W2: =الجدول2[[#This Row],[قيمة الوحدة ]]*0.15 -> 93378 | X2: =الجدول2[[#This Row],[قيمة الوحدة ]]*0.1 -> 62252 | Y2: =الجدول2[[#This Row],[قيمة الوحدة ]]*0.05 -> 31126 | Z2: =SUM(الجدول2[[#This Row],[تحصيل 4-2026 إيصال الى 70%]:[تحصيل 11-2026 إيصال الى 100%]])+الجدول2[[#This Row],[إجمالي الدفعات المحصلة]] -> 622520 | AA2: =الجدول2[[#This Row],[اجمالي الوحدة المحصلة]]-الجدول2[[#This Row],[قيمة الوحدة ]] -> 0
A3: 2 | B3: هدى بنت صالح بن عبدالرحمن القنيطير | C3: الأرضي | D3: 143.03 | E3: مجلس | 3 غرف | صالة | مطبخ | 3 حمام | مستودع | F3: كاش -دفعات | G3: 593633 | H3: 46071 | J3: =SUMIF('الدفعات والتحصيل'!B:B,الجدول2[[#This Row],[رقم الوحدة]],'الدفعات والتحصيل'!D:D) -> 415543.1 | K3: =IFERROR(الجدول2[[#This Row],[إجمالي الدفعات المحصلة]]/الجدول2[[#This Row],[قيمة الوحدة ]],0) -> 0.7 | L3: ='العملاء والوحدات'!$G3-'العملاء والوحدات'!$J3 -> 178089.9 | M3: =الجدول2[[#This Row],[قيمة الوحدة ]]/1.035 -> 573558.45 | N3: =الجدول2[[#This Row],[قيمة الوحدة بدون السعي ]]*0.035 -> 20074.546 | O3: =الجدول2[[#This Row],[العمولة ]]*0.15 -> 3011.1819 | P3: =الجدول2[[#This Row],[ضريبة العمولة ]]+الجدول2[[#This Row],[العمولة ]] -> 23085.728 | Q3: 5750 | R3: =الجدول2[[#This Row],[مكافاة البيع ]]+الجدول2[[#This Row],[العمولة شاملة الضريبة ]] -> 28835.728 | S3: =الجدول2[[#This Row],[العمولة + مكافاة البيع]] -> 28835.728 | T3: =الجدول2[[#This Row],[العمولة + مكافاة البيع]]-الجدول2[[#This Row],[المسدد من العمولة ]] -> 0 | V3: =الجدول2[[#This Row],[قيمة الوحدة ]]*0.7-الجدول2[[#This Row],[إجمالي الدفعات المحصلة]] -> 0 | W3: =الجدول2[[#This Row],[قيمة الوحدة ]]*0.15 -> 89044.95 | X3: =الجدول2[[#This Row],[قيمة الوحدة ]]*0.1 -> 59363.3 | Y3: =الجدول2[[#This Row],[قيمة الوحدة ]]*0.05 -> 29681.65 | Z3: =SUM(الجدول2[[#This Row],[تحصيل 4-2026 إيصال الى 70%]:[تحصيل 11-2026 إيصال الى 100%]])+الجدول2[[#This Row],[إجمالي الدفعات المحصلة]] -> 593633 | AA3: =الجدول2[[#This Row],[اجمالي الوحدة المحصلة]]-الجدول2[[#This Row],[قيمة الوحدة ]] -> 0
A4: 3 | B4: فاطمه بنت علي بن عثمان خرمي | C4: الأرضي | D4: 143.06 | E4: مجلس | 3 غرف | صالة | مطبخ | 3 حمام | مستودع | F4: كاش -دفعات | G4: 574650 | H4: 46055 | J4: =SUMIF('الدفعات والتحصيل'!B:B,الجدول2[[#This Row],[رقم الوحدة]],'الدفعات والتحصيل'!D:D) -> 402255 | K4: =IFERROR(الجدول2[[#This Row],[إجمالي الدفعات المحصلة]]/الجدول2[[#This Row],[قيمة الوحدة ]],0) -> 0.7 | L4: ='العملاء والوحدات'!$G4-'العملاء والوحدات'!$J4 -> 172395 | M4: =الجدول2[[#This Row],[قيمة الوحدة ]]/1.035 -> 555217.39 | N4: =الجدول2[[#This Row],[قيمة الوحدة بدون السعي ]]*0.035 -> 19432.609 | O4: =الجدول2[[#This Row],[العمولة ]]*0.15 -> 2914.8913 | P4: =الجدول2[[#This Row],[ضريبة العمولة ]]+الجدول2[[#This Row],[العمولة ]] -> 22347.5 | R4: =الجدول2[[#This Row],[مكافاة البيع ]]+الجدول2[[#This Row],[العمولة شاملة الضريبة ]] -> 22347.5 | T4: =الجدول2[[#This Row],[العمولة + مكافاة البيع]]-الجدول2[[#This Row],[المسدد من العمولة ]] -> 22347.5 | V4: =الجدول2[[#This Row],[قيمة الوحدة ]]*0.7-الجدول2[[#This Row],[إجمالي الدفعات المحصلة]] -> 0 | W4: =الجدول2[[#This Row],[قيمة الوحدة ]]*0.15 -> 86197.5 | X4: =الجدول2[[#This Row],[قيمة الوحدة ]]*0.1 -> 57465 | Y4: =الجدول2[[#This Row],[قيمة الوحدة ]]*0.05 -> 28732.5 | Z4: =SUM(الجدول2[[#This Row],[تحصيل 4-2026 إيصال الى 70%]:[تحصيل 11-2026 إيصال الى 100%]])+الجدول2[[#This Row],[إجمالي الدفعات المحصلة]] -> 574650 | AA4: =الجدول2[[#This Row],[اجمالي الوحدة المحصلة]]-الجدول2[[#This Row],[قيمة الوحدة ]] -> 0
A5: 4 | B5: عبد الله توفيق عبد الله الحميدى ( نسبة التملك 50% ) & مؤيد بن حسين بن علي الرصاصي (نسبه التملك %50) | C5: الأرضي | D5: 149.04 | E5: مجلس | 3 غرف | صالة | مطبخ | 3 حمام | F5: كاش -دفعات | G5: 619870 | H5: 46069 | J5: =SUMIF('الدفعات والتحصيل'!B:B,الجدول2[[#This Row],[رقم الوحدة]],'الدفعات والتحصيل'!D:D) -> 309935 | K5: =IFERROR(الجدول2[[#This Row],[إجمالي الدفعات المحصلة]]/الجدول2[[#This Row],[قيمة الوحدة ]],0) -> 0.5 | L5: ='العملاء والوحدات'!$G5-'العملاء والوحدات'!$J5 -> 309935 | M5: =الجدول2[[#This Row],[قيمة الوحدة ]]/1.035 -> 598908.21 | N5: =الجدول2[[#This Row],[قيمة الوحدة بدون السعي ]]*0.035 -> 20961.787 | O5: =الجدول2[[#This Row],[العمولة ]]*0.15 -> 3144.2681 | P5: =الجدول2[[#This Row],[ضريبة العمولة ]]+الجدول2[[#This Row],[العمولة ]] -> 24106.056 | Q5: 5750 | R5: =الجدول2[[#This Row],[مكافاة البيع ]]+الجدول2[[#This Row],[العمولة شاملة الضريبة ]] -> 29856.056 | S5: =الجدول2[[#This Row],[العمولة + مكافاة البيع]] -> 29856.056 | T5: =الجدول2[[#This Row],[العمولة + مكافاة البيع]]-الجدول2[[#This Row],[المسدد من العمولة ]] -> 0 | V5: =الجدول2[[#This Row],[قيمة الوحدة ]]*0.7-الجدول2[[#This Row],[إجمالي الدفعات المحصلة]] -> 123974 | W5: =الجدول2[[#This Row],[قيمة الوحدة ]]*0.15 -> 92980.5 | X5: =الجدول2[[#This Row],[قيمة الوحدة ]]*0.1 -> 61987 | Y5: =الجدول2[[#This Row],[قيمة الوحدة ]]*0.05 -> 30993.5 | Z5: =SUM(الجدول2[[#This Row],[تحصيل 4-2026 إيصال الى 70%]:[تحصيل 11-2026 إيصال الى 100%]])+الجدول2[[#This Row],[إجمالي الدفعات المحصلة]] -> 619870 | AA5: =الجدول2[[#This Row],[اجمالي الوحدة المحصلة]]-الجدول2[[#This Row],[قيمة الوحدة ]] -> 0
A6: 5 | B6: صبا زياد مصطفي | C6: الأرضي | D6: 116.25 | E6: مجلس | 2 غرف | صالة | مطبخ | 3 حمام | F6: كاش | G6: 527415 | H6: 46068 | J6: 1 | K6: =IFERROR(الجدول2[[#This Row],[إجمالي الدفعات المحصلة]]/الجدول2[[#This Row],[قيمة الوحدة ]],0) -> 1.8960401e-06 | L6: ='العملاء والوحدات'!$G6-'العملاء والوحدات'!$J6 -> 527414 | M6: =الجدول2[[#This Row],[قيمة الوحدة ]]/1.035 -> 509579.71 | N6: =الجدول2[[#This Row],[قيمة الوحدة بدون السعي ]]*0.035 -> 17835.29 | O6: =الجدول2[[#This Row],[العمولة ]]*0.15 -> 2675.2935 | P6: =الجدول2[[#This Row],[ضريبة العمولة ]]+الجدول2[[#This Row],[العمولة ]] -> 20510.583 | R6: =الجدول2[[#This Row],[مكافاة البيع ]]+الجدول2[[#This Row],[العمولة شاملة الضريبة ]] -> 20510.583 | T6: =الجدول2[[#This Row],[العمولة + مكافاة البيع]]-الجدول2[[#This Row],[المسدد من العمولة ]] -> 20510.583 | V6: =الجدول2[[#This Row],[قيمة الوحدة ]]*0.7-الجدول2[[#This Row],[إجمالي الدفعات المحصلة]] -> 369189.5 | W6: =الجدول2[[#This Row],[قيمة الوحدة ]]*0.15 -> 79112.25 | X6: =الجدول2[[#This Row],[قيمة الوحدة ]]*0.1 -> 52741.5 | Y6: =الجدول2[[#This Row],[قيمة الوحدة ]]*0.05 -> 26370.75 | Z6: =SUM(الجدول2[[#This Row],[تحصيل 4-2026 إيصال الى 70%]:[تحصيل 11-2026 إيصال الى 100%]])+الجدول2[[#This Row],[إجمالي الدفعات المحصلة]] -> 527415 | AA6: =الجدول2[[#This Row],[اجمالي الوحدة المحصلة]]-الجدول2[[#This Row],[قيمة الوحدة ]] -> 0
A7: 6 | B7: عبد العزيز فهد بن سعيدان | C7: الأرضي | D7: 152.14 | E7: مجلس | 3 غرف | صالة | مطبخ | 3 حمام | F7: مدعوم | G7: 723293 | H7: 46053 | J7: 1 | K7: =IFERROR(الجدول2[[#This Row],[إجمالي الدفعات المحصلة]]/الجدول2[[#This Row],[قيمة الوحدة ]],0) -> 1.3825656e-06 | L7: ='العملاء والوحدات'!$G7-'العملاء والوحدات'!$J7 -> 723292 | M7: =الجدول2[[#This Row],[قيمة الوحدة ]]/1.035 -> 698833.82 | N7: =الجدول2[[#This Row],[قيمة الوحدة بدون السعي ]]*0.035 -> 24459.184 | O7: =الجدول2[[#This Row],[العمولة ]]*0.15 -> 3668.8775 | P7: =الجدول2[[#This Row],[ضريبة العمولة ]]+الجدول2[[#This Row],[العمولة ]] -> 28128.061 | R7: =الجدول2[[#This Row],[مكافاة البيع ]]+الجدول2[[#This Row],[العمولة شاملة الضريبة ]] -> 28128.061 | T7: =الجدول2[[#This Row],[العمولة + مكافاة البيع]]-الجدول2[[#This Row],[المسدد من العمولة ]] -> 28128.061 | V7: =الجدول2[[#This Row],[قيمة الوحدة ]]*0.7-الجدول2[[#This Row],[إجمالي الدفعات المحصلة]] -> 506304.1 | W7: =الجدول2[[#This Row],[قيمة الوحدة ]]*0.15 -> 108493.95 | X7: =الجدول2[[#This Row],[قيمة الوحدة ]]*0.1 -> 72329.3 | Y7: =الجدول2[[#This Row],[قيمة الوحدة ]]*0.05 -> 36164.65 | Z7: =SUM(الجدول2[[#This Row],[تحصيل 4-2026 إيصال الى 70%]:[تحصيل 11-2026 إيصال الى 100%]])+الجدول2[[#This Row],[إجمالي الدفعات المحصلة]] -> 723293 | AA7: =الجدول2[[#This Row],[اجمالي الوحدة المحصلة]]-الجدول2[[#This Row],[قيمة الوحدة ]] -> 0
A8: 7 | B8: مروان قطان | C8: الأرضي | D8: 152.11 | E8: مجلس | 3 غرف | صالة | مطبخ | 3 حمام | F8: بنك | G8: 723293 | H8: 46051 | J8: 1 | K8: =IFERROR(الجدول2[[#This Row],[إجمالي الدفعات المحصلة]]/الجدول2[[#This Row],[قيمة الوحدة ]],0) -> 1.3825656e-06 | L8: ='العملاء والوحدات'!$G8-'العملاء والوحدات'!$J8 -> 723292 | M8: =الجدول2[[#This Row],[قيمة الوحدة ]]/1.035 -> 698833.82 | N8: =الجدول2[[#This Row],[قيمة الوحدة بدون السعي ]]*0.035 -> 24459.184 | O8: =الجدول2[[#This Row],[العمولة ]]*0.15 -> 3668.8775 | P8: =الجدول2[[#This Row],[ضريبة العمولة ]]+الجدول2[[#This Row],[العمولة ]] -> 28128.061 | R8: =الجدول2[[#This Row],[مكافاة البيع ]]+الجدول2[[#This Row],[العمولة شاملة الضريبة ]] -> 28128.061 | T8: =الجدول2[[#This Row],[العمولة + مكافاة البيع]]-الجدول2[[#This Row],[المسدد من العمولة ]] -> 28128.061 | V8: =الجدول2[[#This Row],[قيمة الوحدة ]]*0.7-الجدول2[[#This Row],[إجمالي الدفعات المحصلة]] -> 506304.1 | W8: =الجدول2[[#This Row],[قيمة الوحدة ]]*0.15 -> 108493.95 | X8: =الجدول2[[#This Row],[قيمة الوحدة ]]*0.1 -> 72329.3 | Y8: =الجدول2[[#This Row],[قيمة الوحدة ]]*0.05 -> 36164.65 | Z8: =SUM(الجدول2[[#This Row],[تحصيل 4-2026 إيصال الى 70%]:[تحصيل 11-2026 إيصال الى 100%]])+الجدول2[[#This Row],[إجمالي الدفعات المحصلة]] -> 723293 | AA8: =الجدول2[[#This Row],[اجمالي الوحدة المحصلة]]-الجدول2[[#This Row],[قيمة الوحدة ]] -> 0
A9: 8 | B9: خالد على ال صريمى | C9: الأرضي | D9: 116.17 | E9: مجلس | 2 غرف | صالة | مطبخ | 3 حمام | F9: بنك | G9: 502300 | H9: 46058 | J9: 1 | K9: =IFERROR(الجدول2[[#This Row],[إجمالي الدفعات المحصلة]]/الجدول2[[#This Row],[قيمة الوحدة ]],0) -> 1.9908421e-06 | L9: ='العملاء والوحدات'!$G9-'العملاء والوحدات'!$J9 -> 502299 | M9: =الجدول2[[#This Row],[قيمة الوحدة ]]/1.035 -> 485314.01 | N9: =الجدول2[[#This Row],[قيمة الوحدة بدون السعي ]]*0.035 -> 16985.99 | O9: =الجدول2[[#This Row],[العمولة ]]*0.15 -> 2547.8986 | P9: =الجدول2[[#This Row],[ضريبة العمولة ]]+الجدول2[[#This Row],[العمولة ]] -> 19533.889 | R9: =الجدول2[[#This Row],[مكافاة البيع ]]+الجدول2[[#This Row],[العمولة شاملة الضريبة ]] -> 19533.889 | T9: =الجدول2[[#This Row],[العمولة + مكافاة البيع]]-الجدول2[[#This Row],[المسدد من العمولة ]] -> 19533.889 | V9: =الجدول2[[#This Row],[قيمة الوحدة ]]*0.7-الجدول2[[#This Row],[إجمالي الدفعات المحصلة]] -> 351609 | W9: =الجدول2[[#This Row],[قيمة الوحدة ]]*0.15 -> 75345 | X9: =الجدول2[[#This Row],[قيمة الوحدة ]]*0.1 -> 50230 | Y9: =الجدول2[[#This Row],[قيمة الوحدة ]]*0.05 -> 25115 | Z9: =SUM(الجدول2[[#This Row],[تحصيل 4-2026 إيصال الى 70%]:[تحصيل 11-2026 إيصال الى 100%]])+الجدول2[[#This Row],[إجمالي الدفعات المحصلة]] -> 502300 | AA9: =الجدول2[[#This Row],[اجمالي الوحدة المحصلة]]-الجدول2[[#This Row],[قيمة الوحدة ]] -> 0
A10: 9 | B10: عبدالعزيز فهد عبدالعزيز العويدان | C10: الأول | D10: 116.11 | E10: مجلس | 2 غرف | صالة | مطبخ | 3 حمام | F10: حجز من المالك | G10: 482300 | H10: 46033 | J10: 1 | K10: =IFERROR(الجدول2[[#This Row],[إجمالي الدفعات المحصلة]]/الجدول2[[#This Row],[قيمة الوحدة ]],0) -> 2.0733983e-06 | L10: ='العملاء والوحدات'!$G10-'العملاء والوحدات'!$J10 -> 482299 | M10: =الجدول2[[#This Row],[قيمة الوحدة ]]/1.035 -> 465990.34 | N10: =الجدول2[[#This Row],[قيمة الوحدة بدون السعي ]]*0.035 -> 16309.662 | O10: =الجدول2[[#This Row],[العمولة ]]*0.15 -> 2446.4493 | P10: =الجدول2[[#This Row],[ضريبة العمولة ]]+الجدول2[[#This Row],[العمولة ]] -> 18756.111 | R10: =الجدول2[[#This Row],[مكافاة البيع ]]+الجدول2[[#This Row],[العمولة شاملة الضريبة ]] -> 18756.111 | T10: =الجدول2[[#This Row],[العمولة + مكافاة البيع]]-الجدول2[[#This Row],[المسدد من العمولة ]] -> 18756.111 | V10: =الجدول2[[#This Row],[قيمة الوحدة ]]*0.7-الجدول2[[#This Row],[إجمالي الدفعات المحصلة]] -> 337609 | W10: =الجدول2[[#This Row],[قيمة الوحدة ]]*0.15 -> 72345 | X10: =الجدول2[[#This Row],[قيمة الوحدة ]]*0.1 -> 48230 | Y10: =الجدول2[[#This Row],[قيمة الوحدة ]]*0.05 -> 24115 | Z10: =SUM(الجدول2[[#This Row],[تحصيل 4-2026 إيصال الى 70%]:[تحصيل 11-2026 إيصال الى 100%]])+الجدول2[[#This Row],[إجمالي الدفعات المحصلة]] -> 482300 | AA10: =الجدول2[[#This Row],[اجمالي الوحدة المحصلة]]-الجدول2[[#This Row],[قيمة الوحدة ]] -> 0
A11: 10 | B11: عبد الرحمن فهد محمد المطوع | C11: الأول | D11: 132 | E11: مجلس | 3 غرف | صالة | مطبخ | 3 حمام | F11: كاش | G11: 507350 | H11: 46047 | J11: =SUMIF('الدفعات والتحصيل'!B:B,الجدول2[[#This Row],[رقم الوحدة]],'الدفعات والتحصيل'!D:D) -> 253675 | K11: =IFERROR(الجدول2[[#This Row],[إجمالي الدفعات المحصلة]]/الجدول2[[#This Row],[قيمة الوحدة ]],0) -> 0.5 | L11: ='العملاء والوحدات'!$G11-'العملاء والوحدات'!$J11 -> 253675 | M11: =الجدول2[[#This Row],[قيمة الوحدة ]]/1.035 -> 490193.24 | N11: =الجدول2[[#This Row],[قيمة الوحدة بدون السعي ]]*0.035 -> 17156.763 | O11: =الجدول2[[#This Row],[العمولة ]]*0.15 -> 2573.5145 | P11: =الجدول2[[#This Row],[ضريبة العمولة ]]+الجدول2[[#This Row],[العمولة ]] -> 19730.278 | R11: =الجدول2[[#This Row],[مكافاة البيع ]]+الجدول2[[#This Row],[العمولة شاملة الضريبة ]] -> 19730.278 | T11: =الجدول2[[#This Row],[العمولة + مكافاة البيع]]-الجدول2[[#This Row],[المسدد من العمولة ]] -> 19730.278 | V11: =الجدول2[[#This Row],[قيمة الوحدة ]]*0.7-الجدول2[[#This Row],[إجمالي الدفعات المحصلة]] -> 101470 | W11: =الجدول2[[#This Row],[قيمة الوحدة ]]*0.15 -> 76102.5 | X11: =الجدول2[[#This Row],[قيمة الوحدة ]]*0.1 -> 50735 | Y11: =الجدول2[[#This Row],[قيمة الوحدة ]]*0.05 -> 25367.5 | Z11: =SUM(الجدول2[[#This Row],[تحصيل 4-2026 إيصال الى 70%]:[تحصيل 11-2026 إيصال الى 100%]])+الجدول2[[#This Row],[إجمالي الدفعات المحصلة]] -> 507350 | AA11: =الجدول2[[#This Row],[اجمالي الوحدة المحصلة]]-الجدول2[[#This Row],[قيمة الوحدة ]] -> 0
A12: 11 | B12: عبدالسلام بن علي بن عثمان البراك | C12: الأول | D12: 131.63 | E12: مجلس | 2 غرف | صالة | مطبخ | 3 حمام | F12: كاش | G12: 563686 | H12: 46065 | J12: =SUMIF('الدفعات والتحصيل'!B:B,الجدول2[[#This Row],[رقم الوحدة]],'الدفعات والتحصيل'!D:D) -> 281843 | K12: =IFERROR(الجدول2[[#This Row],[إجمالي الدفعات المحصلة]]/الجدول2[[#This Row],[قيمة الوحدة ]],0) -> 0.5 | L12: ='العملاء والوحدات'!$G12-'العملاء والوحدات'!$J12 -> 281843 | M12: =الجدول2[[#This Row],[قيمة الوحدة ]]/1.035 -> 544624.15 | N12: =الجدول2[[#This Row],[قيمة الوحدة بدون السعي ]]*0.035 -> 19061.845 | O12: =الجدول2[[#This Row],[العمولة ]]*0.15 -> 2859.2768 | P12: =الجدول2[[#This Row],[ضريبة العمولة ]]+الجدول2[[#This Row],[العمولة ]] -> 21921.122 | Q12: 5750 | R12: =الجدول2[[#This Row],[مكافاة البيع ]]+الجدول2[[#This Row],[العمولة شاملة الضريبة ]] -> 27671.122 | S12: =الجدول2[[#This Row],[العمولة + مكافاة البيع]] -> 27671.122 | T12: =الجدول2[[#This Row],[العمولة + مكافاة البيع]]-الجدول2[[#This Row],[المسدد من العمولة ]] -> 0 | V12: =الجدول2[[#This Row],[قيمة الوحدة ]]*0.7-الجدول2[[#This Row],[إجمالي الدفعات المحصلة]] -> 112737.2 | W12: =الجدول2[[#This Row],[قيمة الوحدة ]]*0.15 -> 84552.9 | X12: =الجدول2[[#This Row],[قيمة الوحدة ]]*0.1 -> 56368.6 | Y12: =الجدول2[[#This Row],[قيمة الوحدة ]]*0.05 -> 28184.3 | Z12: =SUM(الجدول2[[#This Row],[تحصيل 4-2026 إيصال الى 70%]:[تحصيل 11-2026 إيصال الى 100%]])+الجدول2[[#This Row],[إجمالي الدفعات المحصلة]] -> 563686 | AA12: =الجدول2[[#This Row],[اجمالي الوحدة المحصلة]]-الجدول2[[#This Row],[قيمة الوحدة ]] -> 0
A13: 12 | B13: منى بنت سعود بن موسى آل الرقيب التميمي | C13: الأول | D13: 115.99 | E13: مجلس | 2 غرف | صالة | مطبخ | 3 حمام | F13: بنك /كاش | G13: 497000 | H13: 46054 | J13: =SUMIF('الدفعات والتحصيل'!B:B,الجدول2[[#This Row],[رقم الوحدة]],'الدفعات والتحصيل'!D:D) -> 347900 | K13: =IFERROR(الجدول2[[#This Row],[إجمالي الدفعات المحصلة]]/الجدول2[[#This Row],[قيمة الوحدة ]],0) -> 0.7 | L13: ='العملاء والوحدات'!$G13-'العملاء والوحدات'!$J13 -> 149100 | M13: =الجدول2[[#This Row],[قيمة الوحدة ]]/1.035 -> 480193.24 | N13: =الجدول2[[#This Row],[قيمة الوحدة بدون السعي ]]*0.035 -> 16806.763 | O13: =الجدول2[[#This Row],[العمولة ]]*0.15 -> 2521.0145 | P13: =الجدول2[[#This Row],[ضريبة العمولة ]]+الجدول2[[#This Row],[العمولة ]] -> 19327.778 | Q13: 4888 | R13: =الجدول2[[#This Row],[مكافاة البيع ]]+الجدول2[[#This Row],[العمولة شاملة الضريبة ]] -> 24215.778 | S13: =الجدول2[[#This Row],[العمولة + مكافاة البيع]] -> 24215.778 | T13: =الجدول2[[#This Row],[العمولة + مكافاة البيع]]-الجدول2[[#This Row],[المسدد من العمولة ]] -> 0 | V13: =الجدول2[[#This Row],[قيمة الوحدة ]]*0.7-الجدول2[[#This Row],[إجمالي الدفعات المحصلة]] -> 0 | W13: =الجدول2[[#This Row],[قيمة الوحدة ]]*0.15 -> 74550 | X13: =الجدول2[[#This Row],[قيمة الوحدة ]]*0.1 -> 49700 | Y13: =الجدول2[[#This Row],[قيمة الوحدة ]]*0.05 -> 24850 | Z13: =SUM(الجدول2[[#This Row],[تحصيل 4-2026 إيصال الى 70%]:[تحصيل 11-2026 إيصال الى 100%]])+الجدول2[[#This Row],[إجمالي الدفعات المحصلة]] -> 497000 | AA13: =الجدول2[[#This Row],[اجمالي الوحدة المحصلة]]-الجدول2[[#This Row],[قيمة الوحدة ]] -> 0
A14: 13 | B14: مازن العنزى | C14: الأول | D14: 118.04 | E14: مجلس | 2 غرف | صالة | مطبخ | 3 حمام | F14: كاش | G14: 491400 | H14: 46049 | J14: 1 | K14: =IFERROR(الجدول2[[#This Row],[إجمالي الدفعات المحصلة]]/الجدول2[[#This Row],[قيمة الوحدة ]],0) -> 2.035002e-06 | L14: ='العملاء والوحدات'!$G14-'العملاء والوحدات'!$J14 -> 491399 | M14: =الجدول2[[#This Row],[قيمة الوحدة ]]/1.035 -> 474782.61 | N14: =الجدول2[[#This Row],[قيمة الوحدة بدون السعي ]]*0.035 -> 16617.391 | O14: =الجدول2[[#This Row],[العمولة ]]*0.15 -> 2492.6087 | P14: =الجدول2[[#This Row],[ضريبة العمولة ]]+الجدول2[[#This Row],[العمولة ]] -> 19110 | R14: =الجدول2[[#This Row],[مكافاة البيع ]]+الجدول2[[#This Row],[العمولة شاملة الضريبة ]] -> 19110 | T14: =الجدول2[[#This Row],[العمولة + مكافاة البيع]]-الجدول2[[#This Row],[المسدد من العمولة ]] -> 19110 | V14: =الجدول2[[#This Row],[قيمة الوحدة ]]*0.7-الجدول2[[#This Row],[إجمالي الدفعات المحصلة]] -> 343979 | W14: =الجدول2[[#This Row],[قيمة الوحدة ]]*0.15 -> 73710 | X14: =الجدول2[[#This Row],[قيمة الوحدة ]]*0.1 -> 49140 | Y14: =الجدول2[[#This Row],[قيمة الوحدة ]]*0.05 -> 24570 | Z14: =SUM(الجدول2[[#This Row],[تحصيل 4-2026 إيصال الى 70%]:[تحصيل 11-2026 إيصال الى 100%]])+الجدول2[[#This Row],[إجمالي الدفعات المحصلة]] -> 491400 | AA14: =الجدول2[[#This Row],[اجمالي الوحدة المحصلة]]-الجدول2[[#This Row],[قيمة الوحدة ]] -> 0
A15: 14 | B15: بندر بن عبدالله بن مطلق العقل | C15: الأول | D15: 140.56 | E15: مجلس | 3 غرف | صالة | مطبخ | 3 حمام | F15: دفعات -كاش | G15: 546000 | H15: 46051 | J15: =SUMIF('الدفعات والتحصيل'!B:B,الجدول2[[#This Row],[رقم الوحدة]],'الدفعات والتحصيل'!D:D) -> 273000 | K15: =IFERROR(الجدول2[[#This Row],[إجمالي الدفعات المحصلة]]/الجدول2[[#This Row],[قيمة الوحدة ]],0) -> 0.5 | L15: ='العملاء والوحدات'!$G15-'العملاء والوحدات'!$J15 -> 273000 | M15: =الجدول2[[#This Row],[قيمة الوحدة ]]/1.035 -> 527536.23 | N15: =الجدول2[[#This Row],[قيمة الوحدة بدون السعي ]]*0.035 -> 18463.768 | O15: =الجدول2[[#This Row],[العمولة ]]*0.15 -> 2769.5652 | P15: =الجدول2[[#This Row],[ضريبة العمولة ]]+الجدول2[[#This Row],[العمولة ]] -> 21233.333 | Q15: 5750 | R15: =الجدول2[[#This Row],[مكافاة البيع ]]+الجدول2[[#This Row],[العمولة شاملة الضريبة ]] -> 26983.333 | S15: =الجدول2[[#This Row],[العمولة + مكافاة البيع]] -> 26983.333 | T15: =الجدول2[[#This Row],[العمولة + مكافاة البيع]]-الجدول2[[#This Row],[المسدد من العمولة ]] -> 0 | V15: =الجدول2[[#This Row],[قيمة الوحدة ]]*0.7-الجدول2[[#This Row],[إجمالي الدفعات المحصلة]] -> 109200 | W15: =الجدول2[[#This Row],[قيمة الوحدة ]]*0.15 -> 81900 | X15: =الجدول2[[#This Row],[قيمة الوحدة ]]*0.1 -> 54600 | Y15: =الجدول2[[#This Row],[قيمة الوحدة ]]*0.05 -> 27300 | Z15: =SUM(الجدول2[[#This Row],[تحصيل 4-2026 إيصال الى 70%]:[تحصيل 11-2026 إيصال الى 100%]])+الجدول2[[#This Row],[إجمالي الدفعات المحصلة]] -> 546000 | AA15: =الجدول2[[#This Row],[اجمالي الوحدة المحصلة]]-الجدول2[[#This Row],[قيمة الوحدة ]] -> 0
A16: 15 | B16: حصه بنت محمد بن حمود الجربوع | C16: الأول | D16: 154.32 | E16: مجلس | 3 غرف | صالة | مطبخ | 3 حمام | F16: كاش دفعات | G16: 638800 | H16: 46061 | J16: =SUMIF('الدفعات والتحصيل'!B:B,الجدول2[[#This Row],[رقم الوحدة]],'الدفعات والتحصيل'!D:D) -> 447160 | K16: =IFERROR(الجدول2[[#This Row],[إجمالي الدفعات المحصلة]]/الجدول2[[#This Row],[قيمة الوحدة ]],0) -> 0.7 | L16: ='العملاء والوحدات'!$G16-'العملاء والوحدات'!$J16 -> 191640 | M16: =الجدول2[[#This Row],[قيمة الوحدة ]]/1.035 -> 617198.07 | N16: =الجدول2[[#This Row],[قيمة الوحدة بدون السعي ]]*0.035 -> 21601.932 | O16: =الجدول2[[#This Row],[العمولة ]]*0.15 -> 3240.2899 | P16: =الجدول2[[#This Row],[ضريبة العمولة ]]+الجدول2[[#This Row],[العمولة ]] -> 24842.222 | Q16: 5750 | R16: =الجدول2[[#This Row],[مكافاة البيع ]]+الجدول2[[#This Row],[العمولة شاملة الضريبة ]] -> 30592.222 | S16: =الجدول2[[#This Row],[العمولة + مكافاة البيع]] -> 30592.222 | T16: =الجدول2[[#This Row],[العمولة + مكافاة البيع]]-الجدول2[[#This Row],[المسدد من العمولة ]] -> 0 | V16: =الجدول2[[#This Row],[قيمة الوحدة ]]*0.7-الجدول2[[#This Row],[إجمالي الدفعات المحصلة]] -> 0 | W16: =الجدول2[[#This Row],[قيمة الوحدة ]]*0.15 -> 95820 | X16: =الجدول2[[#This Row],[قيمة الوحدة ]]*0.1 -> 63880 | Y16: =الجدول2[[#This Row],[قيمة الوحدة ]]*0.05 -> 31940 | Z16: =SUM(الجدول2[[#This Row],[تحصيل 4-2026 إيصال الى 70%]:[تحصيل 11-2026 إيصال الى 100%]])+الجدول2[[#This Row],[إجمالي الدفعات المحصلة]] -> 638800 | AA16: =الجدول2[[#This Row],[اجمالي الوحدة المحصلة]]-الجدول2[[#This Row],[قيمة الوحدة ]] -> 0
A17: 16 | B17: صفاء بنت احمد بن حمدان الغامدي | C17: الأول | D17: 153.86 | E17: مجلس | 3 غرف | صالة | مطبخ | 3 حمام | F17: كاش | G17: 670740 | H17: 46063 | J17: =SUMIF('الدفعات والتحصيل'!B:B,الجدول2[[#This Row],[رقم الوحدة]],'الدفعات والتحصيل'!D:D) -> 469518 | K17: =IFERROR(الجدول2[[#This Row],[إجمالي الدفعات المحصلة]]/الجدول2[[#This Row],[قيمة الوحدة ]],0) -> 0.7 | L17: ='العملاء والوحدات'!$G17-'العملاء والوحدات'!$J17 -> 201222 | M17: =الجدول2[[#This Row],[قيمة الوحدة ]]/1.035 -> 648057.97 | N17: =الجدول2[[#This Row],[قيمة الوحدة بدون السعي ]]*0.035 -> 22682.029 | O17: =الجدول2[[#This Row],[العمولة ]]*0.15 -> 3402.3043 | P17: =الجدول2[[#This Row],[ضريبة العمولة ]]+الجدول2[[#This Row],[العمولة ]] -> 26084.333 | Q17: 5750 | R17: =الجدول2[[#This Row],[مكافاة البيع ]]+الجدول2[[#This Row],[العمولة شاملة الضريبة ]] -> 31834.333 | T17: =الجدول2[[#This Row],[العمولة + مكافاة البيع]]-الجدول2[[#This Row],[المسدد من العمولة ]] -> 31834.333 | V17: =الجدول2[[#This Row],[قيمة الوحدة ]]*0.7-الجدول2[[#This Row],[إجمالي الدفعات المحصلة]] -> 0 | W17: =الجدول2[[#This Row],[قيمة الوحدة ]]*0.15 -> 100611 | X17: =الجدول2[[#This Row],[قيمة الوحدة ]]*0.1 -> 67074 | Y17: =الجدول2[[#This Row],[قيمة الوحدة ]]*0.05 -> 33537 | Z17: =SUM(الجدول2[[#This Row],[تحصيل 4-2026 إيصال الى 70%]:[تحصيل 11-2026 إيصال الى 100%]])+الجدول2[[#This Row],[إجمالي الدفعات المحصلة]] -> 670740 | AA17: =الجدول2[[#This Row],[اجمالي الوحدة المحصلة]]-الجدول2[[#This Row],[قيمة الوحدة ]] -> 0
A18: 17 | B18: بندر بن عبدالله بن مطلق العقل | C18: الأول | D18: 140.53 | E18: مجلس | 3 غرف | صالة | مطبخ | 3 حمام | F18: دفعات -كاش | G18: 546000 | H18: 46051 | J18: =SUMIF('الدفعات والتحصيل'!B:B,الجدول2[[#This Row],[رقم الوحدة]],'الدفعات والتحصيل'!D:D) -> 273000 | K18: =IFERROR(الجدول2[[#This Row],[إجمالي الدفعات المحصلة]]/الجدول2[[#This Row],[قيمة الوحدة ]],0) -> 0.5 | L18: ='العملاء والوحدات'!$G18-'العملاء والوحدات'!$J18 -> 273000 | M18: =الجدول2[[#This Row],[قيمة الوحدة ]]/1.035 -> 527536.23 | N18: =الجدول2[[#This Row],[قيمة الوحدة بدون السعي ]]*0.035 -> 18463.768 | O18: =الجدول2[[#This Row],[العمولة ]]*0.15 -> 2769.5652 | P18: =الجدول2[[#This Row],[ضريبة العمولة ]]+الجدول2[[#This Row],[العمولة ]] -> 21233.333 | Q18: 5750 | R18: =الجدول2[[#This Row],[مكافاة البيع ]]+الجدول2[[#This Row],[العمولة شاملة الضريبة ]] -> 26983.333 | S18: =الجدول2[[#This Row],[العمولة + مكافاة البيع]] -> 26983.333 | T18: =الجدول2[[#This Row],[العمولة + مكافاة البيع]]-الجدول2[[#This Row],[المسدد من العمولة ]] -> 0 | V18: =الجدول2[[#This Row],[قيمة الوحدة ]]*0.7-الجدول2[[#This Row],[إجمالي الدفعات المحصلة]] -> 109200 | W18: =الجدول2[[#This Row],[قيمة الوحدة ]]*0.15 -> 81900 | X18: =الجدول2[[#This Row],[قيمة الوحدة ]]*0.1 -> 54600 | Y18: =الجدول2[[#This Row],[قيمة الوحدة ]]*0.05 -> 27300 | Z18: =SUM(الجدول2[[#This Row],[تحصيل 4-2026 إيصال الى 70%]:[تحصيل 11-2026 إيصال الى 100%]])+الجدول2[[#This Row],[إجمالي الدفعات المحصلة]] -> 546000 | AA18: =الجدول2[[#This Row],[اجمالي الوحدة المحصلة]]-الجدول2[[#This Row],[قيمة الوحدة ]] -> 0
A19: 18 | B19: ماجد بن محمد بن عبدالله المطوع | C19: الأول | D19: 118.04 | E19: مجلس | 2 غرف | صالة | مطبخ | 3 حمام | F19: كاش | G19: 491400 | H19: 46049 | J19: =SUMIF('الدفعات والتحصيل'!B:B,الجدول2[[#This Row],[رقم الوحدة]],'الدفعات والتحصيل'!D:D) -> 245700 | K19: =IFERROR(الجدول2[[#This Row],[إجمالي الدفعات المحصلة]]/الجدول2[[#This Row],[قيمة الوحدة ]],0) -> 0.5 | L19: ='العملاء والوحدات'!$G19-'العملاء والوحدات'!$J19 -> 245700 | M19: =الجدول2[[#This Row],[قيمة الوحدة ]]/1.035 -> 474782.61 | N19: =الجدول2[[#This Row],[قيمة الوحدة بدون السعي ]]*0.035 -> 16617.391 | O19: =الجدول2[[#This Row],[العمولة ]]*0.15 -> 2492.6087 | P19: =الجدول2[[#This Row],[ضريبة العمولة ]]+الجدول2[[#This Row],[العمولة ]] -> 19110 | R19: =الجدول2[[#This Row],[مكافاة البيع ]]+الجدول2[[#This Row],[العمولة شاملة الضريبة ]] -> 19110 | S19: =الجدول2[[#This Row],[العمولة + مكافاة البيع]] -> 19110 | T19: =الجدول2[[#This Row],[العمولة + مكافاة البيع]]-الجدول2[[#This Row],[المسدد من العمولة ]] -> 0 | V19: =الجدول2[[#This Row],[قيمة الوحدة ]]*0.7-الجدول2[[#This Row],[إجمالي الدفعات المحصلة]] -> 98280 | W19: =الجدول2[[#This Row],[قيمة الوحدة ]]*0.15 -> 73710 | X19: =الجدول2[[#This Row],[قيمة الوحدة ]]*0.1 -> 49140 | Y19: =الجدول2[[#This Row],[قيمة الوحدة ]]*0.05 -> 24570 | Z19: =SUM(الجدول2[[#This Row],[تحصيل 4-2026 إيصال الى 70%]:[تحصيل 11-2026 إيصال الى 100%]])+الجدول2[[#This Row],[إجمالي الدفعات المحصلة]] -> 491400 | AA19: =الجدول2[[#This Row],[اجمالي الوحدة المحصلة]]-الجدول2[[#This Row],[قيمة الوحدة ]] -> 0
A20: 19 | B20: عاصم عبد العزيز الرزقان | C20: الأول | D20: 115.71 | E20: مجلس | 2 غرف | صالة | مطبخ | 3 حمام | F20: بنك | G20: 477750 | H20: 46040 | J20: 1 | K20: =IFERROR(الجدول2[[#This Row],[إجمالي الدفعات المحصلة]]/الجدول2[[#This Row],[قيمة الوحدة ]],0) -> 2.093145e-06 | L20: ='العملاء والوحدات'!$G20-'العملاء والوحدات'!$J20 -> 477749 | M20: =الجدول2[[#This Row],[قيمة الوحدة ]]/1.035 -> 461594.2 | N20: =الجدول2[[#This Row],[قيمة الوحدة بدون السعي ]]*0.035 -> 16155.797 | O20: =الجدول2[[#This Row],[العمولة ]]*0.15 -> 2423.3696 | P20: =الجدول2[[#This Row],[ضريبة العمولة ]]+الجدول2[[#This Row],[العمولة ]] -> 18579.167 | R20: =الجدول2[[#This Row],[مكافاة البيع ]]+الجدول2[[#This Row],[العمولة شاملة الضريبة ]] -> 18579.167 | T20: =الجدول2[[#This Row],[العمولة + مكافاة البيع]]-الجدول2[[#This Row],[المسدد من العمولة ]] -> 18579.167 | V20: =الجدول2[[#This Row],[قيمة الوحدة ]]*0.7-الجدول2[[#This Row],[إجمالي الدفعات المحصلة]] -> 334424 | W20: =الجدول2[[#This Row],[قيمة الوحدة ]]*0.15 -> 71662.5 | X20: =الجدول2[[#This Row],[قيمة الوحدة ]]*0.1 -> 47775 | Y20: =الجدول2[[#This Row],[قيمة الوحدة ]]*0.05 -> 23887.5 | Z20: =SUM(الجدول2[[#This Row],[تحصيل 4-2026 إيصال الى 70%]:[تحصيل 11-2026 إيصال الى 100%]])+الجدول2[[#This Row],[إجمالي الدفعات المحصلة]] -> 477750 | AA20: =الجدول2[[#This Row],[اجمالي الوحدة المحصلة]]-الجدول2[[#This Row],[قيمة الوحدة ]] -> 0
A21: 20 | B21: احمد طلعت أبو شارب | C21: الأول | D21: 121.64 | E21: مجلس | 2 غرف | صالة | مطبخ | 3 حمام | F21: حجز من المالك | G21: 486850 | H21: حجز من المالك | J21: =SUMIF('الدفعات والتحصيل'!B:B,الجدول2[[#This Row],[رقم الوحدة]],'الدفعات والتحصيل'!D:D) -> 486850 | K21: =IFERROR(الجدول2[[#This Row],[إجمالي الدفعات المحصلة]]/الجدول2[[#This Row],[قيمة الوحدة ]],0) -> 1 | L21: ='العملاء والوحدات'!$G21-'العملاء والوحدات'!$J21 -> 0 | M21: =الجدول2[[#This Row],[قيمة الوحدة ]]/1.035 -> 470386.47 | N21: =الجدول2[[#This Row],[قيمة الوحدة بدون السعي ]]*0.035 -> 16463.527 | O21: =الجدول2[[#This Row],[العمولة ]]*0.15 -> 2469.529 | P21: =الجدول2[[#This Row],[ضريبة العمولة ]]+الجدول2[[#This Row],[العمولة ]] -> 18933.056 | R21: =الجدول2[[#This Row],[مكافاة البيع ]]+الجدول2[[#This Row],[العمولة شاملة الضريبة ]] -> 18933.056 | T21: =الجدول2[[#This Row],[العمولة + مكافاة البيع]]-الجدول2[[#This Row],[المسدد من العمولة ]] -> 18933.056 | V21: 0 | W21: 0 | X21: 0 | Y21: 0 | Z21: =SUM(الجدول2[[#This Row],[تحصيل 4-2026 إيصال الى 70%]:[تحصيل 11-2026 إيصال الى 100%]])+الجدول2[[#This Row],[إجمالي الدفعات المحصلة]] -> 486850 | AA21: =الجدول2[[#This Row],[اجمالي الوحدة المحصلة]]-الجدول2[[#This Row],[قيمة الوحدة ]] -> 0
A22: 21 | B22: عبد الرحمن فهد محمد المطوع | C22: الأول | D22: 137.28 | E22: مجلس | 3 غرف | صالة | مطبخ | 3 حمام | F22: كاش | G22: 521000 | H22: 46047 | J22: =SUMIF('الدفعات والتحصيل'!B:B,الجدول2[[#This Row],[رقم الوحدة]],'الدفعات والتحصيل'!D:D) -> 260500 | K22: =IFERROR(الجدول2[[#This Row],[إجمالي الدفعات المحصلة]]/الجدول2[[#This Row],[قيمة الوحدة ]],0) -> 0.5 | L22: ='العملاء والوحدات'!$G22-'العملاء والوحدات'!$J22 -> 260500 | M22: =الجدول2[[#This Row],[قيمة الوحدة ]]/1.035 -> 503381.64 | N22: =الجدول2[[#This Row],[قيمة الوحدة بدون السعي ]]*0.035 -> 17618.357 | O22: =الجدول2[[#This Row],[العمولة ]]*0.15 -> 2642.7536 | P22: =الجدول2[[#This Row],[ضريبة العمولة ]]+الجدول2[[#This Row],[العمولة ]] -> 20261.111 | Q22: 5750 | R22: =الجدول2[[#This Row],[مكافاة البيع ]]+الجدول2[[#This Row],[العمولة شاملة الضريبة ]] -> 26011.111 | T22: =الجدول2[[#This Row],[العمولة + مكافاة البيع]]-الجدول2[[#This Row],[المسدد من العمولة ]] -> 26011.111 | V22: =الجدول2[[#This Row],[قيمة الوحدة ]]*0.7-الجدول2[[#This Row],[إجمالي الدفعات المحصلة]] -> 104200 | W22: =الجدول2[[#This Row],[قيمة الوحدة ]]*0.15 -> 78150 | X22: =الجدول2[[#This Row],[قيمة الوحدة ]]*0.1 -> 52100 | Y22: =الجدول2[[#This Row],[قيمة الوحدة ]]*0.05 -> 26050 | Z22: =SUM(الجدول2[[#This Row],[تحصيل 4-2026 إيصال الى 70%]:[تحصيل 11-2026 إيصال الى 100%]])+الجدول2[[#This Row],[إجمالي الدفعات المحصلة]] -> 521000 | AA22: =الجدول2[[#This Row],[اجمالي الوحدة المحصلة]]-الجدول2[[#This Row],[قيمة الوحدة ]] -> 0
A23: 22 | B23: عبدالعزيز فهد عبدالعزيز العويدان | C23: الأول | D23: 116.05 | E23: مجلس | 2 غرف | صالة | مطبخ | 3 حمام | F23: حجز من المالك | G23: 482300 | H23: 46033 | J23: 1 | K23: =IFERROR(الجدول2[[#This Row],[إجمالي الدفعات المحصلة]]/الجدول2[[#This Row],[قيمة الوحدة ]],0) -> 2.0733983e-06 | L23: ='العملاء والوحدات'!$G23-'العملاء والوحدات'!$J23 -> 482299 | M23: =الجدول2[[#This Row],[قيمة الوحدة ]]/1.035 -> 465990.34 | N23: =الجدول2[[#This Row],[قيمة الوحدة بدون السعي ]]*0.035 -> 16309.662 | O23: =الجدول2[[#This Row],[العمولة ]]*0.15 -> 2446.4493 | P23: =الجدول2[[#This Row],[ضريبة العمولة ]]+الجدول2[[#This Row],[العمولة ]] -> 18756.111 | R23: =الجدول2[[#This Row],[مكافاة البيع ]]+الجدول2[[#This Row],[العمولة شاملة الضريبة ]] -> 18756.111 | T23: =الجدول2[[#This Row],[العمولة + مكافاة البيع]]-الجدول2[[#This Row],[المسدد من العمولة ]] -> 18756.111 | V23: =الجدول2[[#This Row],[قيمة الوحدة ]]*0.7-الجدول2[[#This Row],[إجمالي الدفعات المحصلة]] -> 337609 | W23: =الجدول2[[#This Row],[قيمة الوحدة ]]*0.15 -> 72345 | X23: =الجدول2[[#This Row],[قيمة الوحدة ]]*0.1 -> 48230 | Y23: =الجدول2[[#This Row],[قيمة الوحدة ]]*0.05 -> 24115 | Z23: =SUM(الجدول2[[#This Row],[تحصيل 4-2026 إيصال الى 70%]:[تحصيل 11-2026 إيصال الى 100%]])+الجدول2[[#This Row],[إجمالي الدفعات المحصلة]] -> 482300 | AA23: =الجدول2[[#This Row],[اجمالي الوحدة المحصلة]]-الجدول2[[#This Row],[قيمة الوحدة ]] -> 0
A24: 23 | B24: روعة سعيد حلوة | C24: الأول | D24: 134.96 | E24: مجلس | 3 غرف | صالة | مطبخ | 3 حمام | F24: حجز من المالك | G24: 546000 | H24: 46046 | J24: =SUMIF('الدفعات والتحصيل'!B:B,الجدول2[[#This Row],[رقم الوحدة]],'الدفعات والتحصيل'!D:D) -> 273000 | K24: =IFERROR(الجدول2[[#This Row],[إجمالي الدفعات المحصلة]]/الجدول2[[#This Row],[قيمة الوحدة ]],0) -> 0.5 | L24: ='العملاء والوحدات'!$G24-'العملاء والوحدات'!$J24 -> 273000 | M24: =الجدول2[[#This Row],[قيمة الوحدة ]]/1.035 -> 527536.23 | N24: =الجدول2[[#This Row],[قيمة الوحدة بدون السعي ]]*0.035 -> 18463.768 | O24: =الجدول2[[#This Row],[العمولة ]]*0.15 -> 2769.5652 | P24: =الجدول2[[#This Row],[ضريبة العمولة ]]+الجدول2[[#This Row],[العمولة ]] -> 21233.333 | R24: =الجدول2[[#This Row],[مكافاة البيع ]]+الجدول2[[#This Row],[العمولة شاملة الضريبة ]] -> 21233.333 | T24: =الجدول2[[#This Row],[العمولة + مكافاة البيع]]-الجدول2[[#This Row],[المسدد من العمولة ]] -> 21233.333 | V24: =الجدول2[[#This Row],[قيمة الوحدة ]]*0.7-الجدول2[[#This Row],[إجمالي الدفعات المحصلة]] -> 109200 | W24: =الجدول2[[#This Row],[قيمة الوحدة ]]*0.15 -> 81900 | X24: =الجدول2[[#This Row],[قيمة الوحدة ]]*0.1 -> 54600 | Y24: =الجدول2[[#This Row],[قيمة الوحدة ]]*0.05 -> 27300 | Z24: =SUM(الجدول2[[#This Row],[تحصيل 4-2026 إيصال الى 70%]:[تحصيل 11-2026 إيصال الى 100%]])+الجدول2[[#This Row],[إجمالي الدفعات المحصلة]] -> 546000 | AA24: =الجدول2[[#This Row],[اجمالي الوحدة المحصلة]]-الجدول2[[#This Row],[قيمة الوحدة ]] -> 0
A25: 24 | B25: عندليب سعيد حلوة | C25: الأول | D25: 137.75 | E25: مجلس | 3 غرف | صالة | مطبخ | 3 حمام | F25: حجز من المالك | G25: 559650 | H25: 46046 | J25: =SUMIF('الدفعات والتحصيل'!B:B,الجدول2[[#This Row],[رقم الوحدة]],'الدفعات والتحصيل'!D:D) -> 279825 | K25: =IFERROR(الجدول2[[#This Row],[إجمالي الدفعات المحصلة]]/الجدول2[[#This Row],[قيمة الوحدة ]],0) -> 0.5 | L25: ='العملاء والوحدات'!$G25-'العملاء والوحدات'!$J25 -> 279825 | M25: =الجدول2[[#This Row],[قيمة الوحدة ]]/1.035 -> 540724.64 | N25: =الجدول2[[#This Row],[قيمة الوحدة بدون السعي ]]*0.035 -> 18925.362 | O25: =الجدول2[[#This Row],[العمولة ]]*0.15 -> 2838.8043 | P25: =الجدول2[[#This Row],[ضريبة العمولة ]]+الجدول2[[#This Row],[العمولة ]] -> 21764.167 | R25: =الجدول2[[#This Row],[مكافاة البيع ]]+الجدول2[[#This Row],[العمولة شاملة الضريبة ]] -> 21764.167 | T25: =الجدول2[[#This Row],[العمولة + مكافاة البيع]]-الجدول2[[#This Row],[المسدد من العمولة ]] -> 21764.167 | V25: =الجدول2[[#This Row],[قيمة الوحدة ]]*0.7-الجدول2[[#This Row],[إجمالي الدفعات المحصلة]] -> 111930 | W25: =الجدول2[[#This Row],[قيمة الوحدة ]]*0.15 -> 83947.5 | X25: =الجدول2[[#This Row],[قيمة الوحدة ]]*0.1 -> 55965 | Y25: =الجدول2[[#This Row],[قيمة الوحدة ]]*0.05 -> 27982.5 | Z25: =SUM(الجدول2[[#This Row],[تحصيل 4-2026 إيصال الى 70%]:[تحصيل 11-2026 إيصال الى 100%]])+الجدول2[[#This Row],[إجمالي الدفعات المحصلة]] -> 559650 | AA25: =الجدول2[[#This Row],[اجمالي الوحدة المحصلة]]-الجدول2[[#This Row],[قيمة الوحدة ]] -> 0
A26: 25 | B26: هيلة محمد عبدالله الصعب | C26: الثاني | D26: 120.01 | E26: مجلس | 2 غرف | صالة | مطبخ | 3 حمام | F26: كاش | G26: 559650 | H26: 46048 | J26: =SUMIF('الدفعات والتحصيل'!B:B,الجدول2[[#This Row],[رقم الوحدة]],'الدفعات والتحصيل'!D:D) -> 391755 | K26: =IFERROR(الجدول2[[#This Row],[إجمالي الدفعات المحصلة]]/الجدول2[[#This Row],[قيمة الوحدة ]],0) -> 0.7 | L26: ='العملاء والوحدات'!$G26-'العملاء والوحدات'!$J26 -> 167895 | M26: =الجدول2[[#This Row],[قيمة الوحدة ]]/1.035 -> 540724.64 | N26: =الجدول2[[#This Row],[قيمة الوحدة بدون السعي ]]*0.035 -> 18925.362 | O26: =الجدول2[[#This Row],[العمولة ]]*0.15 -> 2838.8043 | P26: =الجدول2[[#This Row],[ضريبة العمولة ]]+الجدول2[[#This Row],[العمولة ]] -> 21764.167 | R26: =الجدول2[[#This Row],[مكافاة البيع ]]+الجدول2[[#This Row],[العمولة شاملة الضريبة ]] -> 21764.167 | S26: =الجدول2[[#This Row],[العمولة + مكافاة البيع]] -> 21764.167 | T26: =الجدول2[[#This Row],[العمولة + مكافاة البيع]]-الجدول2[[#This Row],[المسدد من العمولة ]] -> 0 | V26: =الجدول2[[#This Row],[قيمة الوحدة ]]*0.7-الجدول2[[#This Row],[إجمالي الدفعات المحصلة]] -> 0 | W26: =الجدول2[[#This Row],[قيمة الوحدة ]]*0.15 -> 83947.5 | X26: =الجدول2[[#This Row],[قيمة الوحدة ]]*0.1 -> 55965 | Y26: =الجدول2[[#This Row],[قيمة الوحدة ]]*0.05 -> 27982.5 | Z26: =SUM(الجدول2[[#This Row],[تحصيل 4-2026 إيصال الى 70%]:[تحصيل 11-2026 إيصال الى 100%]])+الجدول2[[#This Row],[إجمالي الدفعات المحصلة]] -> 559650 | AA26: =الجدول2[[#This Row],[اجمالي الوحدة المحصلة]]-الجدول2[[#This Row],[قيمة الوحدة ]] -> 0
A27: 26 | B27: باسل بن توفيق ابن احمد بوعيد | C27: الثاني | D27: 167 | E27: مجلس | 3 غرف | صالة | مطبخ | 3 حمام | مستودع | F27: بنك غير مدعوم | G27: 703000 | H27: 46050 | J27: =SUMIF('الدفعات والتحصيل'!B:B,الجدول2[[#This Row],[رقم الوحدة]],'الدفعات والتحصيل'!D:D) -> 140600 | K27: =IFERROR(الجدول2[[#This Row],[إجمالي الدفعات المحصلة]]/الجدول2[[#This Row],[قيمة الوحدة ]],0) -> 0.2 | L27: ='العملاء والوحدات'!$G27-'العملاء والوحدات'!$J27 -> 562400 | M27: =الجدول2[[#This Row],[قيمة الوحدة ]]/1.035 -> 679227.05 | N27: =الجدول2[[#This Row],[قيمة الوحدة بدون السعي ]]*0.035 -> 23772.947 | O27: =الجدول2[[#This Row],[العمولة ]]*0.15 -> 3565.942 | P27: =الجدول2[[#This Row],[ضريبة العمولة ]]+الجدول2[[#This Row],[العمولة ]] -> 27338.889 | Q27: 0 | R27: =الجدول2[[#This Row],[مكافاة البيع ]]+الجدول2[[#This Row],[العمولة شاملة الضريبة ]] -> 27338.889 | S27: =الجدول2[[#This Row],[العمولة + مكافاة البيع]] -> 27338.889 | T27: =الجدول2[[#This Row],[العمولة + مكافاة البيع]]-الجدول2[[#This Row],[المسدد من العمولة ]] -> 0 | V27: =الجدول2[[#This Row],[قيمة الوحدة ]]*0.7-الجدول2[[#This Row],[إجمالي الدفعات المحصلة]] -> 351500 | W27: =الجدول2[[#This Row],[قيمة الوحدة ]]*0.15 -> 105450 | X27: =الجدول2[[#This Row],[قيمة الوحدة ]]*0.1 -> 70300 | Y27: =الجدول2[[#This Row],[قيمة الوحدة ]]*0.05 -> 35150 | Z27: =SUM(الجدول2[[#This Row],[تحصيل 4-2026 إيصال الى 70%]:[تحصيل 11-2026 إيصال الى 100%]])+الجدول2[[#This Row],[إجمالي الدفعات المحصلة]] -> 703000 | AA27: =الجدول2[[#This Row],[اجمالي الوحدة المحصلة]]-الجدول2[[#This Row],[قيمة الوحدة ]] -> 0
A28: 27 | B28: امجاد محمد | C28: الثاني | D28: 115.83 | E28: مجلس | 2 غرف | صالة | مطبخ | 3 حمام | F28: كاش | G28: 522638 | H28: 46077 | J28: 1 | K28: =IFERROR(الجدول2[[#This Row],[إجمالي الدفعات المحصلة]]/الجدول2[[#This Row],[قيمة الوحدة ]],0) -> 1.9133702e-06 | L28: ='العملاء والوحدات'!$G28-'العملاء والوحدات'!$J28 -> 522637 | M28: =الجدول2[[#This Row],[قيمة الوحدة ]]/1.035 -> 504964.25 | N28: =الجدول2[[#This Row],[قيمة الوحدة بدون السعي ]]*0.035 -> 17673.749 | O28: =الجدول2[[#This Row],[العمولة ]]*0.15 -> 2651.0623 | P28: =الجدول2[[#This Row],[ضريبة العمولة ]]+الجدول2[[#This Row],[العمولة ]] -> 20324.811 | R28: =الجدول2[[#This Row],[مكافاة البيع ]]+الجدول2[[#This Row],[العمولة شاملة الضريبة ]] -> 20324.811 | T28: =الجدول2[[#This Row],[العمولة + مكافاة البيع]]-الجدول2[[#This Row],[المسدد من العمولة ]] -> 20324.811 | V28: =الجدول2[[#This Row],[قيمة الوحدة ]]*0.7-الجدول2[[#This Row],[إجمالي الدفعات المحصلة]] -> 365845.6 | W28: =الجدول2[[#This Row],[قيمة الوحدة ]]*0.15 -> 78395.7 | X28: =الجدول2[[#This Row],[قيمة الوحدة ]]*0.1 -> 52263.8 | Y28: =الجدول2[[#This Row],[قيمة الوحدة ]]*0.05 -> 26131.9 | Z28: =SUM(الجدول2[[#This Row],[تحصيل 4-2026 إيصال الى 70%]:[تحصيل 11-2026 إيصال الى 100%]])+الجدول2[[#This Row],[إجمالي الدفعات المحصلة]] -> 522638 | AA28: =الجدول2[[#This Row],[اجمالي الوحدة المحصلة]]-الجدول2[[#This Row],[قيمة الوحدة ]] -> 0
A29: 28 | B29: مني بنت عل بن سعد ال محيي الغامدي | C29: الثاني | D29: 117.83 | E29: مجلس | 2 غرف | صالة | مطبخ | 3 حمام | F29: كاش | G29: 471400 | H29: 46050 | J29: =SUMIF('الدفعات والتحصيل'!B:B,الجدول2[[#This Row],[رقم الوحدة]],'الدفعات والتحصيل'!D:D) -> 471400 | K29: =IFERROR(الجدول2[[#This Row],[إجمالي الدفعات المحصلة]]/الجدول2[[#This Row],[قيمة الوحدة ]],0) -> 1 | L29: ='العملاء والوحدات'!$G29-'العملاء والوحدات'!$J29 -> 0 | M29: =الجدول2[[#This Row],[قيمة الوحدة ]]/1.035 -> 455458.94 | N29: =الجدول2[[#This Row],[قيمة الوحدة بدون السعي ]]*0.035 -> 15941.063 | O29: =الجدول2[[#This Row],[العمولة ]]*0.15 -> 2391.1594 | P29: =الجدول2[[#This Row],[ضريبة العمولة ]]+الجدول2[[#This Row],[العمولة ]] -> 18332.222 | R29: =الجدول2[[#This Row],[مكافاة البيع ]]+الجدول2[[#This Row],[العمولة شاملة الضريبة ]] -> 18332.222 | S29: =الجدول2[[#This Row],[العمولة + مكافاة البيع]] -> 18332.222 | T29: =الجدول2[[#This Row],[العمولة + مكافاة البيع]]-الجدول2[[#This Row],[المسدد من العمولة ]] -> 0 | V29: 0 | W29: 0 | X29: 0 | Y29: 0 | Z29: 0 | AA29: 0
A30: 29 | B30: يزيد فهد راشد المدهش | C30: الثاني | D30: 140.7 | E30: مجلس | 3 غرف | صالة | مطبخ | 3 حمام | F30: بنك | G30: 579650 | H30: 46054 | J30: 1 | K30: =IFERROR(الجدول2[[#This Row],[إجمالي الدفعات المحصلة]]/الجدول2[[#This Row],[قيمة الوحدة ]],0) -> 1.725179e-06 | L30: ='العملاء والوحدات'!$G30-'العملاء والوحدات'!$J30 -> 579649 | M30: =الجدول2[[#This Row],[قيمة الوحدة ]]/1.035 -> 560048.31 | N30: =الجدول2[[#This Row],[قيمة الوحدة بدون السعي ]]*0.035 -> 19601.691 | O30: =الجدول2[[#This Row],[العمولة ]]*0.15 -> 2940.2536 | P30: =الجدول2[[#This Row],[ضريبة العمولة ]]+الجدول2[[#This Row],[العمولة ]] -> 22541.944 | R30: =الجدول2[[#This Row],[مكافاة البيع ]]+الجدول2[[#This Row],[العمولة شاملة الضريبة ]] -> 22541.944 | T30: =الجدول2[[#This Row],[العمولة + مكافاة البيع]]-الجدول2[[#This Row],[المسدد من العمولة ]] -> 22541.944 | V30: =الجدول2[[#This Row],[قيمة الوحدة ]]*0.7-الجدول2[[#This Row],[إجمالي الدفعات المحصلة]] -> 405754 | W30: =الجدول2[[#This Row],[قيمة الوحدة ]]*0.15 -> 86947.5 | X30: =الجدول2[[#This Row],[قيمة الوحدة ]]*0.1 -> 57965 | Y30: =الجدول2[[#This Row],[قيمة الوحدة ]]*0.05 -> 28982.5 | Z30: =SUM(الجدول2[[#This Row],[تحصيل 4-2026 إيصال الى 70%]:[تحصيل 11-2026 إيصال الى 100%]])+الجدول2[[#This Row],[إجمالي الدفعات المحصلة]] -> 579650 | AA30: =الجدول2[[#This Row],[اجمالي الوحدة المحصلة]]-الجدول2[[#This Row],[قيمة الوحدة ]] -> 0
A31: 30 | B31: أحمد بن سليمان بن عبدالعزيز الخضيري | C31: الثاني | D31: 153.99 | E31: مجلس | 3 غرف | صالة | مطبخ | 3 حمام | F31: كاش | G31: 589700 | H31: 46048 | J31: =SUMIF('الدفعات والتحصيل'!B:B,الجدول2[[#This Row],[رقم الوحدة]],'الدفعات والتحصيل'!D:D) -> 412790 | K31: =IFERROR(الجدول2[[#This Row],[إجمالي الدفعات المحصلة]]/الجدول2[[#This Row],[قيمة الوحدة ]],0) -> 0.7 | L31: ='العملاء والوحدات'!$G31-'العملاء والوحدات'!$J31 -> 176910 | M31: =الجدول2[[#This Row],[قيمة الوحدة ]]/1.035 -> 569758.45 | N31: =الجدول2[[#This Row],[قيمة الوحدة بدون السعي ]]*0.035 -> 19941.546 | O31: =الجدول2[[#This Row],[العمولة ]]*0.15 -> 2991.2319 | P31: =الجدول2[[#This Row],[ضريبة العمولة ]]+الجدول2[[#This Row],[العمولة ]] -> 22932.778 | R31: =الجدول2[[#This Row],[مكافاة البيع ]]+الجدول2[[#This Row],[العمولة شاملة الضريبة ]] -> 22932.778 | S31: =الجدول2[[#This Row],[العمولة + مكافاة البيع]] -> 22932.778 | T31: =الجدول2[[#This Row],[العمولة + مكافاة البيع]]-الجدول2[[#This Row],[المسدد من العمولة ]] -> 0 | V31: =الجدول2[[#This Row],[قيمة الوحدة ]]*0.7-الجدول2[[#This Row],[إجمالي الدفعات المحصلة]] -> 0 | W31: =الجدول2[[#This Row],[قيمة الوحدة ]]*0.15 -> 88455 | X31: =الجدول2[[#This Row],[قيمة الوحدة ]]*0.1 -> 58970 | Y31: =الجدول2[[#This Row],[قيمة الوحدة ]]*0.05 -> 29485 | Z31: =SUM(الجدول2[[#This Row],[تحصيل 4-2026 إيصال الى 70%]:[تحصيل 11-2026 إيصال الى 100%]])+الجدول2[[#This Row],[إجمالي الدفعات المحصلة]] -> 589700 | AA31: =الجدول2[[#This Row],[اجمالي الوحدة المحصلة]]-الجدول2[[#This Row],[قيمة الوحدة ]] -> 0
A32: 31 | B32: أحمد بن سليمان بن عبدالعزيز الخضيري | C32: الثاني | D32: 154.07 | E32: مجلس | 3 غرف | صالة | مطبخ | 3 حمام | F32: كاش | G32: 589700 | H32: 46049 | J32: =SUMIF('الدفعات والتحصيل'!B:B,الجدول2[[#This Row],[رقم الوحدة]],'الدفعات والتحصيل'!D:D) -> 412790 | K32: =IFERROR(الجدول2[[#This Row],[إجمالي الدفعات المحصلة]]/الجدول2[[#This Row],[قيمة الوحدة ]],0) -> 0.7 | L32: ='العملاء والوحدات'!$G32-'العملاء والوحدات'!$J32 -> 176910 | M32: =الجدول2[[#This Row],[قيمة الوحدة ]]/1.035 -> 569758.45 | N32: =الجدول2[[#This Row],[قيمة الوحدة بدون السعي ]]*0.035 -> 19941.546 | O32: =الجدول2[[#This Row],[العمولة ]]*0.15 -> 2991.2319 | P32: =الجدول2[[#This Row],[ضريبة العمولة ]]+الجدول2[[#This Row],[العمولة ]] -> 22932.778 | R32: =الجدول2[[#This Row],[مكافاة البيع ]]+الجدول2[[#This Row],[العمولة شاملة الضريبة ]] -> 22932.778 | S32: =الجدول2[[#This Row],[العمولة + مكافاة البيع]] -> 22932.778 | T32: =الجدول2[[#This Row],[العمولة + مكافاة البيع]]-الجدول2[[#This Row],[المسدد من العمولة ]] -> 0 | V32: =الجدول2[[#This Row],[قيمة الوحدة ]]*0.7-الجدول2[[#This Row],[إجمالي الدفعات المحصلة]] -> 0 | W32: =الجدول2[[#This Row],[قيمة الوحدة ]]*0.15 -> 88455 | X32: =الجدول2[[#This Row],[قيمة الوحدة ]]*0.1 -> 58970 | Y32: =الجدول2[[#This Row],[قيمة الوحدة ]]*0.05 -> 29485 | Z32: =SUM(الجدول2[[#This Row],[تحصيل 4-2026 إيصال الى 70%]:[تحصيل 11-2026 إيصال الى 100%]])+الجدول2[[#This Row],[إجمالي الدفعات المحصلة]] -> 589700 | AA32: =الجدول2[[#This Row],[اجمالي الوحدة المحصلة]]-الجدول2[[#This Row],[قيمة الوحدة ]] -> 0
A33: 32 | B33: عاصم محمد العمار | C33: الثاني | D33: 140.63 | E33: مجلس | 3 غرف | صالة | مطبخ | 3 حمام | F33: بنك مدعوم | G33: 613410 | H33: 46060 | J33: 1 | K33: =IFERROR(الجدول2[[#This Row],[إجمالي الدفعات المحصلة]]/الجدول2[[#This Row],[قيمة الوحدة ]],0) -> 1.630231e-06 | L33: ='العملاء والوحدات'!$G33-'العملاء والوحدات'!$J33 -> 613409 | M33: =الجدول2[[#This Row],[قيمة الوحدة ]]/1.035 -> 592666.67 | N33: =الجدول2[[#This Row],[قيمة الوحدة بدون السعي ]]*0.035 -> 20743.333 | O33: =الجدول2[[#This Row],[العمولة ]]*0.15 -> 3111.5 | P33: =الجدول2[[#This Row],[ضريبة العمولة ]]+الجدول2[[#This Row],[العمولة ]] -> 23854.833 | R33: =الجدول2[[#This Row],[مكافاة البيع ]]+الجدول2[[#This Row],[العمولة شاملة الضريبة ]] -> 23854.833 | T33: =الجدول2[[#This Row],[العمولة + مكافاة البيع]]-الجدول2[[#This Row],[المسدد من العمولة ]] -> 23854.833 | V33: =الجدول2[[#This Row],[قيمة الوحدة ]]*0.7-الجدول2[[#This Row],[إجمالي الدفعات المحصلة]] -> 429386 | W33: =الجدول2[[#This Row],[قيمة الوحدة ]]*0.15 -> 92011.5 | X33: =الجدول2[[#This Row],[قيمة الوحدة ]]*0.1 -> 61341 | Y33: =الجدول2[[#This Row],[قيمة الوحدة ]]*0.05 -> 30670.5 | Z33: =SUM(الجدول2[[#This Row],[تحصيل 4-2026 إيصال الى 70%]:[تحصيل 11-2026 إيصال الى 100%]])+الجدول2[[#This Row],[إجمالي الدفعات المحصلة]] -> 613410 | AA33: =الجدول2[[#This Row],[اجمالي الوحدة المحصلة]]-الجدول2[[#This Row],[قيمة الوحدة ]] -> 0
A34: 33 | B34: عبد الرحمن دخيل احمد الملحم | C34: الثاني | D34: 118.21 | E34: مجلس | 2 غرف | صالة | مطبخ | 3 حمام | F34: كاش -دفعات | G34: 500000 | H34: 46055 | J34: =SUMIF('الدفعات والتحصيل'!B:B,الجدول2[[#This Row],[رقم الوحدة]],'الدفعات والتحصيل'!D:D) -> 250000 | K34: =IFERROR(الجدول2[[#This Row],[إجمالي الدفعات المحصلة]]/الجدول2[[#This Row],[قيمة الوحدة ]],0) -> 0.5 | L34: ='العملاء والوحدات'!$G34-'العملاء والوحدات'!$J34 -> 250000 | M34: =الجدول2[[#This Row],[قيمة الوحدة ]]/1.035 -> 483091.79 | N34: =الجدول2[[#This Row],[قيمة الوحدة بدون السعي ]]*0.035 -> 16908.213 | O34: =الجدول2[[#This Row],[العمولة ]]*0.15 -> 2536.2319 | P34: =الجدول2[[#This Row],[ضريبة العمولة ]]+الجدول2[[#This Row],[العمولة ]] -> 19444.444 | Q34: 5750 | R34: =الجدول2[[#This Row],[مكافاة البيع ]]+الجدول2[[#This Row],[العمولة شاملة الضريبة ]] -> 25194.444 | S34: =الجدول2[[#This Row],[العمولة + مكافاة البيع]] -> 25194.444 | T34: =الجدول2[[#This Row],[العمولة + مكافاة البيع]]-الجدول2[[#This Row],[المسدد من العمولة ]] -> 0 | V34: =الجدول2[[#This Row],[قيمة الوحدة ]]*0.7-الجدول2[[#This Row],[إجمالي الدفعات المحصلة]] -> 100000 | W34: =الجدول2[[#This Row],[قيمة الوحدة ]]*0.15 -> 75000 | X34: =الجدول2[[#This Row],[قيمة الوحدة ]]*0.1 -> 50000 | Y34: =الجدول2[[#This Row],[قيمة الوحدة ]]*0.05 -> 25000 | Z34: =SUM(الجدول2[[#This Row],[تحصيل 4-2026 إيصال الى 70%]:[تحصيل 11-2026 إيصال الى 100%]])+الجدول2[[#This Row],[إجمالي الدفعات المحصلة]] -> 500000 | AA34: =الجدول2[[#This Row],[اجمالي الوحدة المحصلة]]-الجدول2[[#This Row],[قيمة الوحدة ]] -> 0
A35: 34 | B35: محمد بن إبراهيم بن محمد الصبيحي | C35: الثاني | D35: 115.76 | E35: مجلس | 2 غرف | صالة | مطبخ | 3 حمام | F35: كاش | G35: 497750 | H35: 46061 | J35: =SUMIF('الدفعات والتحصيل'!B:B,الجدول2[[#This Row],[رقم الوحدة]],'الدفعات والتحصيل'!D:D) -> 248875 | K35: =IFERROR(الجدول2[[#This Row],[إجمالي الدفعات المحصلة]]/الجدول2[[#This Row],[قيمة الوحدة ]],0) -> 0.5 | L35: ='العملاء والوحدات'!$G35-'العملاء والوحدات'!$J35 -> 248875 | M35: =الجدول2[[#This Row],[قيمة الوحدة ]]/1.035 -> 480917.87 | N35: =الجدول2[[#This Row],[قيمة الوحدة بدون السعي ]]*0.035 -> 16832.126 | O35: =الجدول2[[#This Row],[العمولة ]]*0.15 -> 2524.8188 | P35: =الجدول2[[#This Row],[ضريبة العمولة ]]+الجدول2[[#This Row],[العمولة ]] -> 19356.944 | R35: =الجدول2[[#This Row],[مكافاة البيع ]]+الجدول2[[#This Row],[العمولة شاملة الضريبة ]] -> 19356.944 | T35: =الجدول2[[#This Row],[العمولة + مكافاة البيع]]-الجدول2[[#This Row],[المسدد من العمولة ]] -> 19356.944 | V35: =الجدول2[[#This Row],[قيمة الوحدة ]]*0.7-الجدول2[[#This Row],[إجمالي الدفعات المحصلة]] -> 99550 | W35: =الجدول2[[#This Row],[قيمة الوحدة ]]*0.15 -> 74662.5 | X35: =الجدول2[[#This Row],[قيمة الوحدة ]]*0.1 -> 49775 | Y35: =الجدول2[[#This Row],[قيمة الوحدة ]]*0.05 -> 24887.5 | Z35: =SUM(الجدول2[[#This Row],[تحصيل 4-2026 إيصال الى 70%]:[تحصيل 11-2026 إيصال الى 100%]])+الجدول2[[#This Row],[إجمالي الدفعات المحصلة]] -> 497750 | AA35: =الجدول2[[#This Row],[اجمالي الوحدة المحصلة]]-الجدول2[[#This Row],[قيمة الوحدة ]] -> 0
A36: 35 | B36: محمد خليل نمر هندي | C36: الثاني | D36: 153.84 | E36: مجلس | 2 غرف | صالة | مطبخ | 3 حمام | مستودع | G36: 750735 | J36: =SUMIF('الدفعات والتحصيل'!B:B,الجدول2[[#This Row],[رقم الوحدة]],'الدفعات والتحصيل'!D:D) -> 296400 | K36: =IFERROR(الجدول2[[#This Row],[إجمالي الدفعات المحصلة]]/الجدول2[[#This Row],[قيمة الوحدة ]],0) -> 0.39481308 | L36: ='العملاء والوحدات'!$G36-'العملاء والوحدات'!$J36 -> 454335 | M36: =الجدول2[[#This Row],[قيمة الوحدة ]]/1.035 -> 725347.83 | N36: =الجدول2[[#This Row],[قيمة الوحدة بدون السعي ]]*0.035 -> 25387.174 | O36: =الجدول2[[#This Row],[العمولة ]]*0.15 -> 3808.0761 | P36: =الجدول2[[#This Row],[ضريبة العمولة ]]+الجدول2[[#This Row],[العمولة ]] -> 29195.25 | R36: =الجدول2[[#This Row],[مكافاة البيع ]]+الجدول2[[#This Row],[العمولة شاملة الضريبة ]] -> 29195.25 | T36: =الجدول2[[#This Row],[العمولة + مكافاة البيع]]-الجدول2[[#This Row],[المسدد من العمولة ]] -> 29195.25 | V36: =الجدول2[[#This Row],[قيمة الوحدة ]]*0.7-الجدول2[[#This Row],[إجمالي الدفعات المحصلة]] -> 229114.5 | W36: =الجدول2[[#This Row],[قيمة الوحدة ]]*0.15 -> 112610.25 | X36: =الجدول2[[#This Row],[قيمة الوحدة ]]*0.1 -> 75073.5 | Y36: =الجدول2[[#This Row],[قيمة الوحدة ]]*0.05 -> 37536.75 | Z36: =SUM(الجدول2[[#This Row],[تحصيل 4-2026 إيصال الى 70%]:[تحصيل 11-2026 إيصال الى 100%]])+الجدول2[[#This Row],[إجمالي الدفعات المحصلة]] -> 750735 | AA36: =الجدول2[[#This Row],[اجمالي الوحدة المحصلة]]-الجدول2[[#This Row],[قيمة الوحدة ]] -> 0
